#VRML_SIM R2025a utf8

EXTERNPROTO "https://raw.githubusercontent.com/cyberbotics/webots/R2022b/projects/objects/backgrounds/protos/TexturedBackground.proto"
EXTERNPROTO "https://raw.githubusercontent.com/cyberbotics/webots/R2022b/projects/objects/backgrounds/protos/TexturedBackgroundLight.proto"
EXTERNPROTO "https://raw.githubusercontent.com/cyberbotics/webots/R2025a/projects/objects/floors/protos/Floor.proto"

WorldInfo {
}
Viewpoint {
  orientation -0.4764327339353254 -0.1212491990979171 0.8708102444005957 3.5777747205344834
  position 4.230951265229669 1.7138288301545885 4.556365686199892
  follow "host_robot"
}
TexturedBackground {
}
TexturedBackgroundLight {
}
Floor {
}

Solid {
  translation 0.228372 0.168158 0.15
  children [
    Shape {
      appearance PBRAppearance {
        baseColor 0.7 0.7 0.7
      }
      geometry Box {
        size 1 0.2 0.3
      }
    }
  ]
  name "wall_1"
  boundingObject Box {
    size 1 0.2 0.3
  }
}
Solid {
  translation -0.691499 0.349073 0.15
  rotation 0 0 1 -0.3926996938995747
  children [
    Shape {
      appearance PBRAppearance {
        baseColor 0.7 0.7 0.7
      }
      geometry Box {
        size 1 0.2 0.3
      }
    }
  ]
  name "wall_2"
  boundingObject Box {
    size 1 0.2 0.3
  }
}
Solid {
  translation -1.02618 0.944936 0.15
  rotation 0 0 1 -1.7016996938995748
  children [
    Shape {
      appearance PBRAppearance {
        baseColor 0.7 0.7 0.7
      }
      geometry Box {
        size 1 0.2 0.3
      }
    }
  ]
  name "wall_3"
  boundingObject Box {
    size 1 0.2 0.3
  }
}

Robot {
  translation -0.00177116 0.425896 -4.44089e-16
  rotation -0.7071067811865475 0 0.7071067811865475 0
  children [
    HingeJoint {
      jointParameters HingeJointParameters {
        axis 0 1 0
        anchor 0 0 0.025
      }
      device [
        RotationalMotor {
          name "left wheel motor"
          maxVelocity 20
        }
      ]
      endPoint Solid {
        translation 0 0.045 0.025
        children [
          DEF WHEEL Pose {
            rotation 1 0 0 1.5707996938995747
            children [
              Shape {
                appearance PBRAppearance {
                  baseColor 1 0 0
                  roughness 1
                  metalness 0
                }
                geometry Cylinder {
                  height 0.01
                  radius 0.025
                }
              }
            ]
          }
        ]
        name "left wheel"
        boundingObject USE WHEEL
        physics Physics {
        }
      }
    }
    HingeJoint {
      jointParameters HingeJointParameters {
        axis 0 1 0
        anchor 0 0 0.025
      }
      device [
        RotationalMotor {
          name "right wheel motor"
          maxVelocity 20
        }
      ]
      endPoint Solid {
        translation 0 -0.045 0.025
        children [
          USE WHEEL
        ]
        name "right wheel"
        boundingObject USE WHEEL
        physics Physics {
        }
      }
    }
    Pose {
      translation 0 0 0.0415
      children [
        Shape {
          appearance PBRAppearance {
            baseColor 0 0 1
            roughness 1
            metalness 0
          }
          geometry DEF BODY Cylinder {
            height 0.08
            radius 0.045
          }
        }
      ]
    }
    DistanceSensor {
      translation 0.05 0 0.03
      name "ds_front"
      lookupTable [
        0 0 0
        0.3 100 0
      ]
    }
    DistanceSensor {
      translation 0 -0.05 0.03
      rotation 0 0 1 -1.57
      name "ds_right"
      lookupTable [
        0 0 0
        0.3 100 0
      ]
    }
  ]
  name "host_robot"
  boundingObject Pose {
    translation 0 0 0.0415
    children [
      USE BODY
    ]
  }
  physics Physics {
  }
  controller "<extern>"
}
